<?xml version="1.0"?>

<robot xmlns:xacro="http://ros.org/wiki/xacro">

  <xacro:macro name="sciurus17_left_arm">

    <joint name="${NAME_JOINT_ARM_L_1}" type="revolute">
      <parent link="${NAME_LINK_BODY}" />
      <child link="${NAME_LINK_ARM_L_1}" />
      <origin xyz="0.08083 0.0965 0.2885" rpy="0 0 0"/>
      <limit 
        lower="${JOINT_ARM_L_1_LOWER_LIMIT}" 
        upper="${JOINT_ARM_L_1_UPPER_LIMIT}" 
        effort="${EFFORT_LIMIT}" 
        velocity="${VELOCITY_LIMIT}"/>
      <axis xyz="0 1 0"/>
      <dynamics damping="1.0e-6" friction="0.8"/>
    </joint>

    <link name="${NAME_LINK_ARM_L_1}">
      <visual>
        <origin rpy="-1.5708 0 0" xyz="0.0 0.0 0.0"/>
        <geometry>
          <mesh filename="package://sciurus17_description/meshes/visual/L_Link1.stl" scale="1.0 1.0 1.0"/>
        </geometry>
        <material name="${COLOR_LINK_ARM}"/>
      </visual>
      <collision>
        <origin rpy="-1.5708 0 0" xyz="0.0 0.0 0.0"/>
        <geometry>
          <mesh filename="package://sciurus17_description/meshes/collision/L_Link1.stl" scale="1.0 1.0 1.0"/>
        </geometry>
      </collision>
      <inertial>
        <origin rpy="-1.5708 0 0" xyz="-0.537e-03 46.27e-03 -0.27e-03"/>
        <inertia ixx="170007.992e-09" ixy="13.313e-09" ixz="454.301e-09" iyy="175079.881e-09" iyz="159.916e-09" izz="85282.27e-09"/>
        <mass value="258.0e-03"/>
      </inertial>
    </link>

    <joint name="${NAME_JOINT_ARM_L_2}" type="revolute">
      <parent link="${NAME_LINK_ARM_L_1}" />
      <child link="${NAME_LINK_ARM_L_2}" />
      <origin xyz="0.0 0.064 0.0" rpy="0 0 0"/>
      <limit 
        lower="${JOINT_ARM_L_2_LOWER_LIMIT}" 
        upper="${JOINT_ARM_L_2_UPPER_LIMIT}" 
        effort="${EFFORT_LIMIT}" 
        velocity="${VELOCITY_LIMIT}"/>
      <axis xyz="-1 0 0"/>
      <dynamics damping="1.0e-6" friction="0.8"/>
    </joint>

    <link name="${NAME_LINK_ARM_L_2}">
      <visual>
        <origin rpy="0 -1.5708 0" xyz="0.0 0.0 0.0"/>
        <geometry>
          <mesh filename="package://sciurus17_description/meshes/visual/L_Link2.stl" scale="1.0 1.0 1.0"/>
        </geometry>
        <material name="${COLOR_LINK_ARM}"/>
      </visual>
      <collision>
        <origin rpy="0 -1.5708 0" xyz="0.0 0.0 0.0"/>
        <geometry>
          <mesh filename="package://sciurus17_description/meshes/collision/L_Link2.stl" scale="1.0 1.0 1.0"/>
        </geometry>
      </collision>
      <inertial>
        <origin rpy="0 -1.5708 0" xyz="0.199e-03 33.946e-03 -0.07e-03"/>
        <inertia ixx="172421.741e-09" ixy="-98.964e-09" ixz="-266.684e-09" iyy="99076.413e-09" iyz="-418.743e-09" izz="137151.205e-09"/>
        <mass value="134.0e-03"/>
      </inertial>
    </link>

    <joint name="${NAME_JOINT_ARM_L_3}" type="revolute">
      <parent link="${NAME_LINK_ARM_L_2}" />
      <child link="${NAME_LINK_ARM_L_3}" />
      <origin xyz="0.0 0.065 0.0" rpy="0 0 0"/>
      <limit 
        lower="${JOINT_ARM_L_3_LOWER_LIMIT}"
        upper="${JOINT_ARM_L_3_UPPER_LIMIT}" 
        effort="${EFFORT_LIMIT}" 
        velocity="${VELOCITY_LIMIT}"/>
      <axis xyz="0 1 0"/>
      <dynamics damping="1.0e-6" friction="0.8"/>
    </joint>

    <link name="${NAME_LINK_ARM_L_3}">
      <visual>
        <origin rpy="-1.5708 0 0" xyz="0.0 0.0 0.0"/>
        <geometry>
          <mesh filename="package://sciurus17_description/meshes/visual/L_Link3.stl" scale="1.0 1.0 1.0"/>
        </geometry>
        <material name="${COLOR_LINK_ARM}"/>
      </visual>
      <collision>
        <origin rpy="-1.5708 0 0" xyz="0.0 0.0 0.0"/>
        <geometry>
          <mesh filename="package://sciurus17_description/meshes/collision/L_Link3.stl" scale="1.0 1.0 1.0"/>
        </geometry>
      </collision>
      <inertial>
        <origin rpy="-1.5708 0 0" xyz="-13.943e-03 113.533e-03 0.241e-03"/>
        <inertia ixx="2343035.312e-09" ixy="1178.732e-09" ixz="-72414.462e-09" iyy="2422253.94e-09" iyz="8074.759e-09" izz="237122.927e-09"/>
        <mass value="443.0e-03"/>
      </inertial>
    </link>

    <joint name="${NAME_JOINT_ARM_L_4}" type="revolute">
      <parent link="${NAME_LINK_ARM_L_3}" />
      <child link="${NAME_LINK_ARM_L_4}" />
      <origin xyz="0.0 0.185 0.0" rpy="0 0 0"/>
      <limit 
        lower="${JOINT_ARM_L_4_LOWER_LIMIT}" 
        upper="${JOINT_ARM_L_4_UPPER_LIMIT}" 
        effort="${EFFORT_LIMIT}" 
        velocity="${VELOCITY_LIMIT}"/>
      <axis xyz="0 0 1"/>
      <dynamics damping="1.0e-6" friction="0.8"/>
    </joint>

    <link name="${NAME_LINK_ARM_L_4}">
      <visual>
        <origin rpy="0 0 0" xyz="0.0 0.0 0.0"/>
        <geometry>
          <mesh filename="package://sciurus17_description/meshes/visual/L_Link4.stl" scale="1.0 1.0 1.0"/>
        </geometry>
        <material name="${COLOR_LINK_ARM}"/>
      </visual>
      <collision>
        <origin rpy="0 0 0" xyz="0.0 0.0 0.0"/>
        <geometry>
          <mesh filename="package://sciurus17_description/meshes/collision/L_Link4.stl" scale="1.0 1.0 1.0"/>
        </geometry>
      </collision>
      <inertial>
        <origin rpy="0 0 0" xyz="-8.926e-03 78.626e-03 -0.005e-03"/>
        <inertia ixx="533003.24e-09" ixy="972.381e-09" ixz="220.273e-09" iyy="130793.897e-09" iyz="1226.699e-09" izz="533022.145e-09"/>
        <mass value="238.0e-03"/>
      </inertial>
    </link>

    <joint name="${NAME_JOINT_ARM_L_5}" type="revolute">
      <parent link="${NAME_LINK_ARM_L_4}" />
      <child link="${NAME_LINK_ARM_L_5}" />
      <origin xyz="0.0 0.121 0.0" rpy="0 0 0"/>
      <limit 
        lower="${JOINT_ARM_L_5_LOWER_LIMIT}" 
        upper="${JOINT_ARM_L_5_UPPER_LIMIT}" 
        effort="${EFFORT_LIMIT}" 
        velocity="${VELOCITY_LIMIT}"/>
      <axis xyz="0 1 0"/>
      <dynamics damping="1.0e-6" friction="0.8"/>
    </joint>

    <link name="${NAME_LINK_ARM_L_5}">
      <visual>
        <origin rpy="-1.5708 0 0" xyz="0.0 0.0 0.0"/>
        <geometry>
          <mesh filename="package://sciurus17_description/meshes/visual/L_Link5.stl" scale="1.0 1.0 1.0"/>
        </geometry>
        <material name="${COLOR_LINK_ARM}"/>
      </visual>
      <visual>
        <origin xyz="0.032 0.074 -0.0346" rpy="3.1415926 0 2.0944"/>
        <geometry>
          <mesh filename="package://sciurus17_description/meshes/visual/Logo_Rabbit.stl" scale="1.0 1.0 1.0"/>
        </geometry>
        <material name="red_color">
          <color rgba="0.8984375 0.0 0.0703125 1"/>
        </material>
      </visual>
      <visual>
        <origin xyz="0.013 0.107 -0.0346" rpy="3.1415926 0 2.0944"/>
        <geometry>
          <mesh filename="package://sciurus17_description/meshes/visual/Logo_Corp.stl" scale="1.0 1.0 1.0"/>
        </geometry>
        <material name="black_color">
          <color rgba="0.2 0.2 0.2 1"/>
        </material>
      </visual>
      <collision>
        <origin rpy="-1.5708 0 0" xyz="0.0 0.0 0.0"/>
        <geometry>
          <mesh filename="package://sciurus17_description/meshes/collision/L_Link5.stl" scale="1.0 1.0 1.0"/>
        </geometry>
      </collision>
      <inertial>
        <origin rpy="-1.5708 0 0" xyz="13.732e-03 71.158e-03 -0.348e-03"/>
        <inertia ixx="286973.35e-09" ixy="4321.461e-09" ixz="-19101.45e-09" iyy="282370.572e-09" iyz="-13052.23e-09" izz="125680.836e-09"/>
        <mass value="224.0e-03"/>
      </inertial>
    </link>

    <joint name="${NAME_JOINT_ARMARKER_L}" type="fixed">
      <parent link="${NAME_LINK_ARM_L_5}" />
      <child link="${NAME_LINK_ARMARKER_L}" />
      <origin xyz="0.0467 0.093 0.0" rpy="0 0 0"/>
    </joint>

    <link name="${NAME_LINK_ARMARKER_L}">
      <visual>
        <origin rpy="0 0 0" xyz="0.0 0.0 0.0"/>
        <geometry>
          <cylinder length="0.001" radius="0.001"/>
        </geometry>
        <material name="${COLOR_LINK_ARM}"/>
      </visual>
      <collision>
        <origin rpy="0 0 0" xyz="0.0 0.0 0.0"/>
        <geometry>
          <cylinder length="0.001" radius="0.001"/>
        </geometry>
      </collision>
    </link>

    <joint name="${NAME_JOINT_ARM_L_6}" type="revolute">
      <parent link="${NAME_LINK_ARM_L_5}" />
      <child link="${NAME_LINK_ARM_L_6}" />
      <origin xyz="0.0 0.129 0.0" rpy="0 0 0"/>
      <limit 
        lower="${JOINT_ARM_L_6_LOWER_LIMIT}" 
        upper="${JOINT_ARM_L_6_UPPER_LIMIT}" 
        effort="${EFFORT_LIMIT}" 
        velocity="${VELOCITY_LIMIT}"/>
      <axis xyz="0 0 1"/>
      <dynamics damping="1.0e-6" friction="0.8"/>
    </joint>

    <link name="${NAME_LINK_ARM_L_6}">
      <visual>
        <origin rpy="0 0 0" xyz="0.0 0.0 0.0"/>
        <geometry>
          <mesh filename="package://sciurus17_description/meshes/visual/L_Link6.stl" scale="1.0 1.0 1.0"/>
        </geometry>
        <material name="${COLOR_LINK_ARM}"/>
      </visual>
      <collision>
        <origin rpy="0 0 0" xyz="0.0 0.0 0.0"/>
        <geometry>
          <mesh filename="package://sciurus17_description/meshes/collision/L_Link6.stl" scale="1.0 1.0 1.0"/>
        </geometry>
      </collision>
      <inertial>
        <origin rpy="0 0 0" xyz="-6.173e-03 -3.627e-03 0.744e-03"/>
        <inertia ixx="39902.954e-09" ixy="3014.503e-09" ixz="-613.647e-09" iyy="61099.851e-09" iyz="-361.668e-09" izz="73723.447e-09"/>
        <mass value="140.0e-03"/>
      </inertial>
    </link>

    <joint name="${NAME_JOINT_ARM_L_7}" type="revolute">
      <parent link="${NAME_LINK_ARM_L_6}" />
      <child link="${NAME_LINK_ARM_L_7}" />
      <origin xyz="0.0 0.0191 0.0" rpy="0 0 0"/>
      <limit 
        lower="${JOINT_ARM_L_7_LOWER_LIMIT}" 
        upper="${JOINT_ARM_L_7_UPPER_LIMIT}" 
        effort="${EFFORT_LIMIT}" 
        velocity="${VELOCITY_LIMIT}"/>
      <axis xyz="0 1 0"/>
      <dynamics damping="1.0e-6" friction="0.8"/>
    </joint>

  </xacro:macro>

</robot>
