<?xml version="1.0"?>

<robot xmlns:xacro="http://ros.org/wiki/xacro">

  <xacro:macro name="sciurus17_body">

    <link name="${NAME_LINK_BASE}">
      <visual>
        <geometry>
          <mesh filename="package://sciurus17_description/meshes/visual/Base.stl" scale="1.0 1.0 1.0"/>
        </geometry>
        <material name="${COLOR_LINK_BASE}"/>
      </visual>
      <collision>
        <origin rpy="0 0 0" xyz="0.0 0.0 0.0"/>
        <geometry>
          <mesh filename="package://sciurus17_description/meshes/collision/Base.stl" scale="1.0 1.0 1.0"/>
        </geometry>
      </collision>
      <inertial>
        <origin rpy="0 0 0" xyz="-24.012e-03 0.139e-03 59.566e-03"/>
        <inertia ixx="6398092.663e-09" ixy="-6808.969e-09" ixz="-331509.04e-09" iyy="7611664.357e-09" iyz="2026.354e-09" izz="6331936.461e-09"/>
        <mass value="1722.937e-03"/>
      </inertial>
    </link>

    <joint name="${NAME_JOINT_BODY}" type="revolute">
      <parent link="${NAME_LINK_BASE}" />
      <child link="${NAME_LINK_BODY}" />
      <origin xyz="0.0 0.0 0.1315" rpy="0 0 0"/>
      <limit 
        lower="${JOINT_BODY_LOWER_LIMIT}" 
        upper="${JOINT_BODY_UPPER_LIMIT}" 
        effort="${EFFORT_LIMIT}" 
        velocity="${VELOCITY_LIMIT}"/>
      <axis xyz="0 0 1"/>
      <dynamics damping="1.0e-6" friction="0.8"/>
    </joint>

    <link name="${NAME_LINK_BODY}">
      <visual>
        <geometry>
          <mesh filename="package://sciurus17_description/meshes/visual/Body.stl" scale="1.0 1.0 1.0"/>
        </geometry>
        <material name="${COLOR_LINK_BODY}"/>
      </visual>
      <collision>
        <origin rpy="0 0 0" xyz="0.0 0.0 0.0"/>
        <geometry>
          <mesh filename="package://sciurus17_description/meshes/collision/Body.stl" scale="1.0 1.0 1.0"/>
        </geometry>
      </collision>
      <inertial>
       <origin rpy="0 0 0" xyz="57.11e-03 0.372e-03 238.229e-03"/>
        <inertia ixx="15601031.58e-09" ixy="-15890.903e-09" ixz="-3805596.494e-09" iyy="13969734.5e-09" iyz="-20695.221e-09" izz="8327993.097e-09"/>
        <mass value="1482.929e-03"/>
      </inertial>
    </link>

    <joint name="${NAME_JOINT_CHEST_CAMERA}" type="fixed">
      <parent link="${NAME_LINK_BODY}" />
      <child link="${NAME_LINK_CHEST_CAMERA}" />
      <origin xyz="0.114576 0.0 0.217659" rpy="-2.7925268032 0 -1.5707963268"/>
    </joint>

    <link name="${NAME_LINK_CHEST_CAMERA}"/>

  </xacro:macro>

</robot>
