<?xml version="1.0"?>

<robot xmlns:xacro="http://ros.org/wiki/xacro">

  <xacro:macro name="sciurus17_right_arm">

    <joint name="${NAME_JOINT_ARM_R_1}" type="revolute">
      <parent link="${NAME_LINK_BODY}" />
      <child link="${NAME_LINK_ARM_R_1}" />
      <origin xyz="0.08083 -0.0965 0.2885" rpy="0 0 0"/>
      <limit 
        lower="${JOINT_ARM_R_1_LOWER_LIMIT}" 
        upper="${JOINT_ARM_R_1_UPPER_LIMIT}" 
        effort="${EFFORT_LIMIT}" 
        velocity="${VELOCITY_LIMIT}"/>
      <axis xyz="0 -1 0"/>
      <dynamics damping="1.0e-6" friction="0.8"/>
    </joint>

    <link name="${NAME_LINK_ARM_R_1}">
      <visual>
        <origin rpy="1.5708 0 0" xyz="0.0 0.0 0.0"/>
        <geometry>
          <mesh filename="package://sciurus17_description/meshes/visual/R_Link1.stl" scale="1.0 1.0 1.0"/>
        </geometry>
        <material name="${COLOR_LINK_ARM}"/>
      </visual>
      <collision>
        <origin rpy="1.5708 0 0" xyz="0.0 0.0 0.0"/>
        <geometry>
          <mesh filename="package://sciurus17_description/meshes/collision/R_Link1.stl" scale="1.0 1.0 1.0"/>
        </geometry>
      </collision>
      <inertial>
        <origin rpy="1.5708 0 0" xyz="-0.656e-03 -46.367e-03 -0.264e-03"/>
        <inertia ixx="176217.476e-09" ixy="-5.425e-09" ixz="586.979e-09" iyy="179207.793e-09" iyz="-166.297e-09" izz="87950.071e-09"/>
        <mass value="258.0e-03"/>
      </inertial>
    </link>

    <joint name="${NAME_JOINT_ARM_R_2}" type="revolute">
      <parent link="${NAME_LINK_ARM_R_1}" />
      <child link="${NAME_LINK_ARM_R_2}" />
      <origin xyz="0.0 -0.064 0.0" rpy="0 0 0"/>
      <limit 
        lower="${JOINT_ARM_R_2_LOWER_LIMIT}" 
        upper="${JOINT_ARM_R_2_UPPER_LIMIT}" 
        effort="${EFFORT_LIMIT}" 
        velocity="${VELOCITY_LIMIT}"/>
      <axis xyz="-1 0 0"/>
      <dynamics damping="1.0e-6" friction="0.8"/>
    </joint>

    <link name="${NAME_LINK_ARM_R_2}">
      <visual>
        <origin rpy="0 1.5708 0" xyz="0.0 0.0 0.0"/>
        <geometry>
          <mesh filename="package://sciurus17_description/meshes/visual/R_Link2.stl" scale="1.0 1.0 1.0"/>
        </geometry>
        <material name="${COLOR_LINK_ARM}"/>
      </visual>
      <collision>
        <origin rpy="0 1.5708 0" xyz="0.0 0.0 0.0"/>
        <geometry>
          <mesh filename="package://sciurus17_description/meshes/collision/R_Link2.stl" scale="1.0 1.0 1.0"/>
        </geometry>
      </collision>
      <inertial>
        <origin rpy="0 1.5708 0" xyz="-0.185e-03 -33.96e-03 -0.033e-03"/>
        <inertia ixx="172046.031e-09" ixy="-119.176e-09" ixz="-535.109e-09" iyy="98834.156e-09" iyz="580.743e-09" izz="136915.218e-09"/>
        <mass value="134.0e-03"/>
      </inertial>
    </link>

    <joint name="${NAME_JOINT_ARM_R_3}" type="revolute">
      <parent link="${NAME_LINK_ARM_R_2}" />
      <child link="${NAME_LINK_ARM_R_3}" />
      <origin xyz="0.0 -0.065 0.0" rpy="0 0 0"/>
      <limit 
        lower="${JOINT_ARM_R_3_LOWER_LIMIT}"
        upper="${JOINT_ARM_R_3_UPPER_LIMIT}" 
        effort="${EFFORT_LIMIT}" 
        velocity="${VELOCITY_LIMIT}"/>
      <axis xyz="0 -1 0"/>
      <dynamics damping="1.0e-6" friction="0.8"/>
    </joint>

    <link name="${NAME_LINK_ARM_R_3}">
      <visual>
        <origin rpy="1.5708 0 0" xyz="0.0 0.0 0.0"/>
        <geometry>
          <mesh filename="package://sciurus17_description/meshes/visual/L_Link3.stl" scale="1.0 1.0 1.0"/>
        </geometry>
        <material name="${COLOR_LINK_ARM}"/>
      </visual>
      <collision>
        <origin rpy="1.5708 0 0" xyz="0.0 0.0 0.0"/>
        <geometry>
          <mesh filename="package://sciurus17_description/meshes/collision/L_Link3.stl" scale="1.0 1.0 1.0"/>
        </geometry>
      </collision>
      <inertial>
        <origin rpy="1.5708 0 0" xyz="-13.791e-03 -113.391e-03 0.245e-03"/>
        <inertia ixx="2336253.636e-09" ixy="-1190.372e-09" ixz="-75998.279e-09" iyy="2414711.907e-09" iyz="-8024.912e-09" izz="236305.543e-09"/>
        <mass value="443.0e-03"/>
      </inertial>
    </link>

    <joint name="${NAME_JOINT_ARM_R_4}" type="revolute">
      <parent link="${NAME_LINK_ARM_R_3}" />
      <child link="${NAME_LINK_ARM_R_4}" />
      <origin xyz="0.0 -0.185 0.0" rpy="0 0 0"/>
      <limit 
        lower="${JOINT_ARM_R_4_LOWER_LIMIT}" 
        upper="${JOINT_ARM_R_4_UPPER_LIMIT}" 
        effort="${EFFORT_LIMIT}" 
        velocity="${VELOCITY_LIMIT}"/>
      <axis xyz="0 0 1"/>
      <dynamics damping="1.0e-6" friction="0.8"/>
    </joint>

    <link name="${NAME_LINK_ARM_R_4}">
      <visual>
        <origin rpy="0 0 0" xyz="0.0 0.0 0.0"/>
        <geometry>
          <mesh filename="package://sciurus17_description/meshes/visual/R_Link4.stl" scale="1.0 1.0 1.0"/>
        </geometry>
        <material name="${COLOR_LINK_ARM}"/>
      </visual>
      <collision>
        <origin rpy="0 0 0" xyz="0.0 0.0 0.0"/>
        <geometry>
          <mesh filename="package://sciurus17_description/meshes/collision/R_Link4.stl" scale="1.0 1.0 1.0"/>
        </geometry>
      </collision>
      <inertial>
        <origin rpy="0 0 0" xyz="-8.881e-03 -75.749e-03 0.038e-03"/>
        <inertia ixx="603280.74e-09" ixy="-6670.94e-09" ixz="250.846e-09" iyy="143154.3e-09" iyz="-2309.247e-09" izz="598152.333e-09"/>
        <mass value="238.0e-03"/>
      </inertial>
    </link>

    <joint name="${NAME_JOINT_ARM_R_5}" type="revolute">
      <parent link="${NAME_LINK_ARM_R_4}" />
      <child link="${NAME_LINK_ARM_R_5}" />
      <origin xyz="0.0 -0.121 0.0" rpy="0 0 0"/>
      <limit 
        lower="${JOINT_ARM_R_5_LOWER_LIMIT}" 
        upper="${JOINT_ARM_R_5_UPPER_LIMIT}" 
        effort="${EFFORT_LIMIT}" 
        velocity="${VELOCITY_LIMIT}"/>
      <axis xyz="0 -1 0"/>
      <dynamics damping="1.0e-6" friction="0.8"/>
    </joint>

    <link name="${NAME_LINK_ARM_R_5}">
      <visual>
        <origin rpy="1.5708 0 0" xyz="0.0 0.0 0.0"/>
        <geometry>
          <mesh filename="package://sciurus17_description/meshes/visual/R_Link5.stl" scale="1.0 1.0 1.0"/>
        </geometry>
        <material name="${COLOR_LINK_ARM}"/>
      </visual>
      <visual>
        <origin xyz="0.032 -0.074 0.0345" rpy="0 0 -2.0944"/>
        <geometry>
          <mesh filename="package://sciurus17_description/meshes/visual/Logo_Rabbit.stl" scale="1.0 1.0 1.0"/>
        </geometry>
        <material name="red_color">
          <color rgba="0.8984375 0.0 0.0703125 1"/>
        </material>
      </visual>
      <visual>
        <origin xyz="0.013 -0.107 0.0345" rpy="0 0 -2.0944"/>
        <geometry>
          <mesh filename="package://sciurus17_description/meshes/visual/Logo_Corp.stl" scale="1.0 1.0 1.0"/>
        </geometry>
        <material name="black_color">
          <color rgba="0.2 0.2 0.2 1"/>
        </material>
      </visual>
      <collision>
        <origin rpy="1.5708 0 0" xyz="0.0 0.0 0.0"/>
        <geometry>
          <mesh filename="package://sciurus17_description/meshes/collision/R_Link5.stl" scale="1.0 1.0 1.0"/>
        </geometry>
      </collision>
      <inertial>
        <origin rpy="1.5708 0 0" xyz="13.531e-03 -70.369e-03 -0.304e-03"/>
        <inertia ixx="294726.731e-09" ixy="-4809.196e-09" ixz="-21387.985e-09" iyy="290568.087e-09" iyz="13192.269e-09" izz="125378.656e-09"/>
        <mass value="224.0e-03"/>
      </inertial>
    </link>

    <joint name="${NAME_JOINT_ARMARKER_R}" type="fixed">
      <parent link="${NAME_LINK_ARM_R_5}" />
      <child link="${NAME_LINK_ARMARKER_R}" />
      <origin xyz="0.0467 -0.093 0.0" rpy="0 0 0"/>
    </joint>

    <link name="${NAME_LINK_ARMARKER_R}">
      <visual>
        <origin rpy="0 0 0" xyz="0.0 0.0 0.0"/>
        <geometry>
          <cylinder length="0.001" radius="0.001"/>
        </geometry>
        <material name="${COLOR_LINK_ARM}"/>
      </visual>
      <collision>
        <origin rpy="0 0 0" xyz="0.0 0.0 0.0"/>
        <geometry>
          <cylinder length="0.001" radius="0.001"/>
        </geometry>
      </collision>
    </link>

    <joint name="${NAME_JOINT_ARM_R_6}" type="revolute">
      <parent link="${NAME_LINK_ARM_R_5}" />
      <child link="${NAME_LINK_ARM_R_6}" />
      <origin xyz="0.0 -0.129 0.0" rpy="0 0 0"/>
      <limit 
        lower="${JOINT_ARM_R_6_LOWER_LIMIT}" 
        upper="${JOINT_ARM_R_6_UPPER_LIMIT}" 
        effort="${EFFORT_LIMIT}" 
        velocity="${VELOCITY_LIMIT}"/>
      <axis xyz="0 0 1"/>
      <dynamics damping="1.0e-6" friction="0.8"/>
    </joint>

    <link name="${NAME_LINK_ARM_R_6}">
      <visual>
        <origin rpy="0 0 0" xyz="0.0 0.0 0.0"/>
        <geometry>
          <mesh filename="package://sciurus17_description/meshes/visual/R_Link6.stl" scale="1.0 1.0 1.0"/>
        </geometry>
        <material name="${COLOR_LINK_ARM}"/>
      </visual>
      <collision>
        <origin rpy="0 0 0" xyz="0.0 0.0 0.0"/>
        <geometry>
          <mesh filename="package://sciurus17_description/meshes/collision/R_Link6.stl" scale="1.0 1.0 1.0"/>
        </geometry>
      </collision>
      <inertial>
        <origin rpy="0 0 0" xyz="-6.156e-03 3.583e-03 0.755e-03"/>
        <inertia ixx="39499.661e-09" ixy="-2921.88e-09" ixz="-612.042e-09" iyy="60684.342e-09" iyz="357.397e-09" izz="73112.015e-09"/>
        <mass value="140.0e-03"/>
      </inertial>
    </link>

    <joint name="${NAME_JOINT_ARM_R_7}" type="revolute">
      <parent link="${NAME_LINK_ARM_R_6}" />
      <child link="${NAME_LINK_ARM_R_7}" />
      <origin xyz="0.0 -0.0191 0.0" rpy="0 0 0"/>
      <limit 
        lower="${JOINT_ARM_R_7_LOWER_LIMIT}" 
        upper="${JOINT_ARM_R_7_UPPER_LIMIT}" 
        effort="${EFFORT_LIMIT}" 
        velocity="${VELOCITY_LIMIT}"/>
      <axis xyz="0 -1 0"/>
      <dynamics damping="1.0e-6" friction="0.8"/>
    </joint>

  </xacro:macro>

</robot>
